Workbook

Sheet Painel
A1: DASHBOARD DE ANDAMENTO DO CRM: LEADS, NEGÓCIOS, INSTALAÇÕES, REPAROS E SAÚDE DA CARTEIRA
A2: Simulação com dados 100% fictícios. Tudo é calculado a partir das abas de dados.
A3: Data de referência: | B3: 46310 | C3: (edite para recalcular atrasos e dias sem contato)
A5: Negócios criados | C5: Em andamento | E5: Fechados ganhos | G5: Fechados perdidos | I5: Taxa de conversão
A6: =COUNTA(Negocios!$A$3:$A$82) -> 80 | C6: =COUNTA(Negocios!$A$3:$A$82)-COUNTIF(Negocios!$F$3:$F$82,"Fechado ganho")-COUNTIF(Negocios!$F$3:$F$82,"Fechado perdido") -> 36 | E6: =COUNTIF(Negocios!$F$3:$F$82,"Fechado ganho") -> 28 | G6: =COUNTIF(Negocios!$F$3:$F$82,"Fechado perdido") -> 16 | I6: =IFERROR(COUNTIF(Negocios!$F$3:$F$82,"Fechado ganho")/(COUNTIF(Negocios!$F$3:$F$82,"Fechado ganho")+COUNTIF(Negocios!$F$3:$F$82,"Fechado perdido")),0) -> 0.63636364
A8: Valor em andamento (R$) | C8: Valor ponderado (R$) | E8: Ticket médio ganho (R$) | G8: Instalações concluídas | I8: Pontos de atenção
A9: =SUM(Negocios!$G$3:$G$82)-SUMIFS(Negocios!$G$3:$G$82,Negocios!$F$3:$F$82,"Fechado ganho")-SUMIFS(Negocios!$G$3:$G$82,Negocios!$F$3:$F$82,"Fechado perdido") -> 553000 | C9: =SUM(Negocios!$K$3:$K$82) -> 220540 | E9: =IFERROR(AVERAGEIFS(Negocios!$G$3:$G$82,Negocios!$F$3:$F$82,"Fechado ganho"),0) -> 13503.571 | G9: =IFERROR(COUNTIF(Instalacoes!$F$3:$F$30,"Concluída e validada")/COUNTA(Instalacoes!$A$3:$A$30),0) -> 0.64285714 | I9: =COUNTIF(Negocios!$M$3:$M$82,"Sem contato*")+COUNTIF(Negocios!$M$3:$M$82,"Falta*")+COUNTIF(Instalacoes!$H$3:$H$30,"Atrasada")+COUNTIF(Instalacoes!$H$3:$H$30,"Falta*")+COUNTIF(Reparos!$H$3:$H$10,"Aberto há*") -> 16
A12: Funil por fase
A13: Fase | B13: Negócios | C13: Valor (R$) | D13: % do total
A14: Qualificação | B14: =COUNTIF(Negocios!$F$3:$F$82,$A14) -> 12 | C14: =SUMIFS(Negocios!$G$3:$G$82,Negocios!$F$3:$F$82,$A14) -> 179200 | D14: =IFERROR(B14/COUNTA(Negocios!$A$3:$A$82),0) -> 0.15
A15: Orçamento enviado | B15: =COUNTIF(Negocios!$F$3:$F$82,$A15) -> 14 | C15: =SUMIFS(Negocios!$G$3:$G$82,Negocios!$F$3:$F$82,$A15) -> 196800 | D15: =IFERROR(B15/COUNTA(Negocios!$A$3:$A$82),0) -> 0.175
A16: Negociação | B16: =COUNTIF(Negocios!$F$3:$F$82,$A16) -> 10 | C16: =SUMIFS(Negocios!$G$3:$G$82,Negocios!$F$3:$F$82,$A16) -> 177000 | D16: =IFERROR(B16/COUNTA(Negocios!$A$3:$A$82),0) -> 0.125
A17: Fechado ganho | B17: =COUNTIF(Negocios!$F$3:$F$82,$A17) -> 28 | C17: =SUMIFS(Negocios!$G$3:$G$82,Negocios!$F$3:$F$82,$A17) -> 378100 | D17: =IFERROR(B17/COUNTA(Negocios!$A$3:$A$82),0) -> 0.35
A18: Fechado perdido | B18: =COUNTIF(Negocios!$F$3:$F$82,$A18) -> 16 | C18: =SUMIFS(Negocios!$G$3:$G$82,Negocios!$F$3:$F$82,$A18) -> 167100 | D18: =IFERROR(B18/COUNTA(Negocios!$A$3:$A$82),0) -> 0.2
A19: Origem dos leads
A20: Origem | B20: Negócios | C20: Ganhos | D20: Conversão
A21: WhatsApp | B21: =COUNTIF(Negocios!$C$3:$C$82,$A21) -> 19 | C21: =COUNTIFS(Negocios!$C$3:$C$82,$A21,Negocios!$F$3:$F$82,"Fechado ganho") -> 3 | D21: =IFERROR(C21/(C21+COUNTIFS(Negocios!$C$3:$C$82,$A21,Negocios!$F$3:$F$82,"Fechado perdido")),0) -> 0.375
A22: Instagram | B22: =COUNTIF(Negocios!$C$3:$C$82,$A22) -> 22 | C22: =COUNTIFS(Negocios!$C$3:$C$82,$A22,Negocios!$F$3:$F$82,"Fechado ganho") -> 8 | D22: =IFERROR(C22/(C22+COUNTIFS(Negocios!$C$3:$C$82,$A22,Negocios!$F$3:$F$82,"Fechado perdido")),0) -> 0.72727273
A23: Indicação | B23: =COUNTIF(Negocios!$C$3:$C$82,$A23) -> 19 | C23: =COUNTIFS(Negocios!$C$3:$C$82,$A23,Negocios!$F$3:$F$82,"Fechado ganho") -> 9 | D23: =IFERROR(C23/(C23+COUNTIFS(Negocios!$C$3:$C$82,$A23,Negocios!$F$3:$F$82,"Fechado perdido")),0) -> 0.9
A24: Site | B24: =COUNTIF(Negocios!$C$3:$C$82,$A24) -> 20 | C24: =COUNTIFS(Negocios!$C$3:$C$82,$A24,Negocios!$F$3:$F$82,"Fechado ganho") -> 8 | D24: =IFERROR(C24/(C24+COUNTIFS(Negocios!$C$3:$C$82,$A24,Negocios!$F$3:$F$82,"Fechado perdido")),0) -> 0.53333333
A25: Instalações por status
A26: Status | B26: Instalações | C26: % do total | D26: Atrasadas
A27: Agendada | B27: =COUNTIF(Instalacoes!$F$3:$F$30,$A27) -> 3 | C27: =IFERROR(B27/COUNTA(Instalacoes!$A$3:$A$30),0) -> 0.10714286 | D27: =COUNTIFS(Instalacoes!$F$3:$F$30,$A27,Instalacoes!$H$3:$H$30,"Atrasada") -> 0
A28: Material conferido | B28: =COUNTIF(Instalacoes!$F$3:$F$30,$A28) -> 3 | C28: =IFERROR(B28/COUNTA(Instalacoes!$A$3:$A$30),0) -> 0.10714286 | D28: =COUNTIFS(Instalacoes!$F$3:$F$30,$A28,Instalacoes!$H$3:$H$30,"Atrasada") -> 1
A29: Em execução | B29: =COUNTIF(Instalacoes!$F$3:$F$30,$A29) -> 4 | C29: =IFERROR(B29/COUNTA(Instalacoes!$A$3:$A$30),0) -> 0.14285714 | D29: =COUNTIFS(Instalacoes!$F$3:$F$30,$A29,Instalacoes!$H$3:$H$30,"Atrasada") -> 3
A30: Concluída e validada | B30: =COUNTIF(Instalacoes!$F$3:$F$30,$A30) -> 18 | C30: =IFERROR(B30/COUNTA(Instalacoes!$A$3:$A$30),0) -> 0.64285714 | D30: =COUNTIFS(Instalacoes!$F$3:$F$30,$A30,Instalacoes!$H$3:$H$30,"Atrasada") -> 0
A31: Reparos por causa
A32: Causa | B32: Reparos | C32: Em aberto
A33: Falha de aplicação | B33: =COUNTIF(Reparos!$D$3:$D$10,$A33) -> 2 | C33: =COUNTIFS(Reparos!$D$3:$D$10,$A33,Reparos!$E$3:$E$10,"<>Resolvido") -> 2
A34: Material com defeito | B34: =COUNTIF(Reparos!$D$3:$D$10,$A34) -> 2 | C34: =COUNTIFS(Reparos!$D$3:$D$10,$A34,Reparos!$E$3:$E$10,"<>Resolvido") -> 1
A35: Preparo inadequado do local | B35: =COUNTIF(Reparos!$D$3:$D$10,$A35) -> 0 | C35: =COUNTIFS(Reparos!$D$3:$D$10,$A35,Reparos!$E$3:$E$10,"<>Resolvido") -> 0
A36: Medida incorreta | B36: =COUNTIF(Reparos!$D$3:$D$10,$A36) -> 2 | C36: =COUNTIFS(Reparos!$D$3:$D$10,$A36,Reparos!$E$3:$E$10,"<>Resolvido") -> 0
A37: Dano após a instalação | B37: =COUNTIF(Reparos!$D$3:$D$10,$A37) -> 2 | C37: =COUNTIFS(Reparos!$D$3:$D$10,$A37,Reparos!$E$3:$E$10,"<>Resolvido") -> 1
A39: Saúde da carteira
A40: Status | B40: Clientes | C40: % do total
A41: Saudável | B41: =COUNTIF(Contas!$C$3:$C$30,$A41) -> 9 | C41: =IFERROR(B41/COUNTA(Contas!$A$3:$A$30),0) -> 0.32142857
A42: Atenção | B42: =COUNTIF(Contas!$C$3:$C$30,$A42) -> 14 | C42: =IFERROR(B42/COUNTA(Contas!$A$3:$A$30),0) -> 0.5
A43: Risco | B43: =COUNTIF(Contas!$C$3:$C$30,$A43) -> 5 | C43: =IFERROR(B43/COUNTA(Contas!$A$3:$A$30),0) -> 0.17857143
A45: Negócios criados por mês (e ganhos desses negócios)
A46: Mês | B46: Criados | C46: Ganhos
...

Sheet Como usar
A1: COMO USAR
A3: Legenda: célula amarela com texto azul = você preenche. Célula cinza = fórmula, não edite.
A4: Exemplo de linha em Negocios: N-001 | Cliente 001 | WhatsApp | 02/06/2026 | Atendente A | Negociação | 12.000 | 10/10/2026.
A5: 1. Registre cada negócio na aba Negocios (fase, valor, último contato e, se perdido, o motivo).
A6: 2. Quando o negócio for ganho, crie a linha na aba Instalacoes e cadastre o cliente em Contas com o health score.
A7: 3. Reparos ficam na aba Reparos, ligados à instalação de origem.
A8: 4. Ajuste a Data de referência no Painel para recalcular atrasos e dias sem contato.
A9: 5. Para incluir mais linhas, estenda as fórmulas das abas e dos intervalos do Painel até o novo fim dos dados.
A11: PONTOS DE ATENÇÃO CONTADOS NO PAINEL
A12: Negócio aberto sem contato há mais de 7 dias · negócio perdido sem motivo · instalação atrasada · instalação concluída sem checklist · reparo aberto há mais de 7 dias.
A14: PREMISSAS
A15: Todos os dados são fictícios. Probabilidades por fase (aba Listas), prazo de 7 dias e faixas do health score (80 e 50) são exemplos editáveis.
A16: Ganhos por mês consideram o mês de criação do negócio.

Sheet Negocios
A1: NEGÓCIOS (do lead ao fechamento)
A2: ID | B2: Cliente | C2: Origem | D2: Data de criação | E2: Responsável | F2: Fase | G2: Valor (R$) | H2: Último contato | I2: Motivo da perda | J2: Probabilidade | K2: Valor ponderado (R$) | L2: Dias sem contato | M2: Alerta | N2: Mês de criação
A3: N-001 | B3: Cliente 067 | C3: Indicação | D3: 46177 | E3: Atendente B | F3: Fechado ganho | G3: 20500 | H3: 46189 | J3: =IFERROR(VLOOKUP(F3,Listas!$A$2:$B$6,2,FALSE()),0) -> 1 | K3: =IF(OR(F3="Fechado ganho",F3="Fechado perdido"),0,G3*J3) -> 0 | L3: =IF(OR(F3="Fechado ganho",F3="Fechado perdido"),"",Painel!$B$3-H3) | M3: =IF(AND(F3="Fechado perdido",I3=""),"Falta motivo da perda",IF(OR(F3="Fechado ganho",F3="Fechado perdido"),"",IF(Painel!$B$3-H3>7,"Sem contato há mais de 7 dias","OK"))) | N3: =MONTH(D3) -> 6
A4: N-002 | B4: Cliente 022 | C4: Indicação | D4: 46178 | E4: Atendente A | F4: Fechado ganho | G4: 15100 | H4: 46192 | J4: =IFERROR(VLOOKUP(F4,Listas!$A$2:$B$6,2,FALSE()),0) -> 1 | K4: =IF(OR(F4="Fechado ganho",F4="Fechado perdido"),0,G4*J4) -> 0 | L4: =IF(OR(F4="Fechado ganho",F4="Fechado perdido"),"",Painel!$B$3-H4) | M4: =IF(AND(F4="Fechado perdido",I4=""),"Falta motivo da perda",IF(OR(F4="Fechado ganho",F4="Fechado perdido"),"",IF(Painel!$B$3-H4>7,"Sem contato há mais de 7 dias","OK"))) | N4: =MONTH(D4) -> 6
A5: N-003 | B5: Cliente 007 | C5: Site | D5: 46179 | E5: Atendente A | F5: Fechado ganho | G5: 8300 | H5: 46187 | J5: =IFERROR(VLOOKUP(F5,Listas!$A$2:$B$6,2,FALSE()),0) -> 1 | K5: =IF(OR(F5="Fechado ganho",F5="Fechado perdido"),0,G5*J5) -> 0 | L5: =IF(OR(F5="Fechado ganho",F5="Fechado perdido"),"",Painel!$B$3-H5) | M5: =IF(AND(F5="Fechado perdido",I5=""),"Falta motivo da perda",IF(OR(F5="Fechado ganho",F5="Fechado perdido"),"",IF(Painel!$B$3-H5>7,"Sem contato há mais de 7 dias","OK"))) | N5: =MONTH(D5) -> 6
A6: N-004 | B6: Cliente 023 | C6: Site | D6: 46179 | E6: Atendente A | F6: Fechado ganho | G6: 18300 | H6: 46184 | J6: =IFERROR(VLOOKUP(F6,Listas!$A$2:$B$6,2,FALSE()),0) -> 1 | K6: =IF(OR(F6="Fechado ganho",F6="Fechado perdido"),0,G6*J6) -> 0 | L6: =IF(OR(F6="Fechado ganho",F6="Fechado perdido"),"",Painel!$B$3-H6) | M6: =IF(AND(F6="Fechado perdido",I6=""),"Falta motivo da perda",IF(OR(F6="Fechado ganho",F6="Fechado perdido"),"",IF(Painel!$B$3-H6>7,"Sem contato há mais de 7 dias","OK"))) | N6: =MONTH(D6) -> 6
A7: N-005 | B7: Cliente 066 | C7: Instagram | D7: 46179 | E7: Atendente A | F7: Fechado ganho | G7: 3900 | H7: 46188 | J7: =IFERROR(VLOOKUP(F7,Listas!$A$2:$B$6,2,FALSE()),0) -> 1 | K7: =IF(OR(F7="Fechado ganho",F7="Fechado perdido"),0,G7*J7) -> 0 | L7: =IF(OR(F7="Fechado ganho",F7="Fechado perdido"),"",Painel!$B$3-H7) | M7: =IF(AND(F7="Fechado perdido",I7=""),"Falta motivo da perda",IF(OR(F7="Fechado ganho",F7="Fechado perdido"),"",IF(Painel!$B$3-H7>7,"Sem contato há mais de 7 dias","OK"))) | N7: =MONTH(D7) -> 6
A8: N-006 | B8: Cliente 027 | C8: Site | D8: 46181 | E8: Atendente B | F8: Fechado ganho | G8: 15700 | H8: 46184 | J8: =IFERROR(VLOOKUP(F8,Listas!$A$2:$B$6,2,FALSE()),0) -> 1 | K8: =IF(OR(F8="Fechado ganho",F8="Fechado perdido"),0,G8*J8) -> 0 | L8: =IF(OR(F8="Fechado ganho",F8="Fechado perdido"),"",Painel!$B$3-H8) | M8: =IF(AND(F8="Fechado perdido",I8=""),"Falta motivo da perda",IF(OR(F8="Fechado ganho",F8="Fechado perdido"),"",IF(Painel!$B$3-H8>7,"Sem contato há mais de 7 dias","OK"))) | N8: =MONTH(D8) -> 6
A9: N-007 | B9: Cliente 052 | C9: Site | D9: 46183 | E9: Atendente B | F9: Fechado ganho | G9: 14200 | H9: 46196 | J9: =IFERROR(VLOOKUP(F9,Listas!$A$2:$B$6,2,FALSE()),0) -> 1 | K9: =IF(OR(F9="Fechado ganho",F9="Fechado perdido"),0,G9*J9) -> 0 | L9: =IF(OR(F9="Fechado ganho",F9="Fechado perdido"),"",Painel!$B$3-H9) | M9: =IF(AND(F9="Fechado perdido",I9=""),"Falta motivo da perda",IF(OR(F9="Fechado ganho",F9="Fechado perdido"),"",IF(Painel!$B$3-H9>7,"Sem contato há mais de 7 dias","OK"))) | N9: =MONTH(D9) -> 6
A10: N-008 | B10: Cliente 008 | C10: Site | D10: 46184 | E10: Atendente B | F10: Fechado ganho | G10: 6700 | H10: 46193 | J10: =IFERROR(VLOOKUP(F10,Listas!$A$2:$B$6,2,FALSE()),0) -> 1 | K10: =IF(OR(F10="Fechado ganho",F10="Fechado perdido"),0,G10*J10) -> 0 | L10: =IF(OR(F10="Fechado ganho",F10="Fechado perdido"),"",Painel!$B$3-H10) | M10: =IF(AND(F10="Fechado perdido",I10=""),"Falta motivo da perda",IF(OR(F10="Fechado ganho",F10="Fechado perdido"),"",IF(Painel!$B$3-H10>7,"Sem contato há mais de 7 dias","OK"))) | N10: =MONTH(D10) -> 6
A11: N-009 | B11: Cliente 017 | C11: Site | D11: 46191 | E11: Atendente A | F11: Fechado perdido | G11: 6200 | H11: 46201 | I11: Escolheu outro fornecedor | J11: =IFERROR(VLOOKUP(F11,Listas!$A$2:$B$6,2,FALSE()),0) -> 0 | K11: =IF(OR(F11="Fechado ganho",F11="Fechado perdido"),0,G11*J11) -> 0 | L11: =IF(OR(F11="Fechado ganho",F11="Fechado perdido"),"",Painel!$B$3-H11) | M11: =IF(AND(F11="Fechado perdido",I11=""),"Falta motivo da perda",IF(OR(F11="Fechado ganho",F11="Fechado perdido"),"",IF(Painel!$B$3-H11>7,"Sem contato há mais de 7 dias","OK"))) | N11: =MONTH(D11) -> 6
A12: N-010 | B12: Cliente 031 | C12: Instagram | D12: 46196 | E12: Atendente A | F12: Fechado perdido | G12: 15300 | H12: 46199 | I12: Desistiu do projeto | J12: =IFERROR(VLOOKUP(F12,Listas!$A$2:$B$6,2,FALSE()),0) -> 0 | K12: =IF(OR(F12="Fechado ganho",F12="Fechado perdido"),0,G12*J12) -> 0 | L12: =IF(OR(F12="Fechado ganho",F12="Fechado perdido"),"",Painel!$B$3-H12) | M12: =IF(AND(F12="Fechado perdido",I12=""),"Falta motivo da perda",IF(OR(F12="Fechado ganho",F12="Fechado perdido"),"",IF(Painel!$B$3-H12>7,"Sem contato há mais de 7 dias","OK"))) | N12: =MONTH(D12) -> 6
A13: N-011 | B13: Cliente 075 | C13: Instagram | D13: 46198 | E13: Atendente A | F13: Fechado ganho | G13: 14100 | H13: 46214 | J13: =IFERROR(VLOOKUP(F13,Listas!$A$2:$B$6,2,FALSE()),0) -> 1 | K13: =IF(OR(F13="Fechado ganho",F13="Fechado perdido"),0,G13*J13) -> 0 | L13: =IF(OR(F13="Fechado ganho",F13="Fechado perdido"),"",Painel!$B$3-H13) | M13: =IF(AND(F13="Fechado perdido",I13=""),"Falta motivo da perda",IF(OR(F13="Fechado ganho",F13="Fechado perdido"),"",IF(Painel!$B$3-H13>7,"Sem contato há mais de 7 dias","OK"))) | N13: =MONTH(D13) -> 6
A14: N-012 | B14: Cliente 015 | C14: Indicação | D14: 46200 | E14: Atendente A | F14: Fechado ganho | G14: 5700 | H14: 46204 | J14: =IFERROR(VLOOKUP(F14,Listas!$A$2:$B$6,2,FALSE()),0) -> 1 | K14: =IF(OR(F14="Fechado ganho",F14="Fechado perdido"),0,G14*J14) -> 0 | L14: =IF(OR(F14="Fechado ganho",F14="Fechado perdido"),"",Painel!$B$3-H14) | M14: =IF(AND(F14="Fechado perdido",I14=""),"Falta motivo da perda",IF(OR(F14="Fechado ganho",F14="Fechado perdido"),"",IF(Painel!$B$3-H14>7,"Sem contato há mais de 7 dias","OK"))) | N14: =MONTH(D14) -> 6
A15: N-013 | B15: Cliente 074 | C15: Indicação | D15: 46207 | E15: Atendente B | F15: Fechado ganho | G15: 21600 | H15: 46212 | J15: =IFERROR(VLOOKUP(F15,Listas!$A$2:$B$6,2,FALSE()),0) -> 1 | K15: =IF(OR(F15="Fechado ganho",F15="Fechado perdido"),0,G15*J15) -> 0 | L15: =IF(OR(F15="Fechado ganho",F15="Fechado perdido"),"",Painel!$B$3-H15) | M15: =IF(AND(F15="Fechado perdido",I15=""),"Falta motivo da perda",IF(OR(F15="Fechado ganho",F15="Fechado perdido"),"",IF(Painel!$B$3-H15>7,"Sem contato há mais de 7 dias","OK"))) | N15: =MONTH(D15) -> 7
A16: N-014 | B16: Cliente 033 | C16: Instagram | D16: 46210 | E16: Atendente B | F16: Fechado ganho | G16: 20300 | H16: 46219 | J16: =IFERROR(VLOOKUP(F16,Listas!$A$2:$B$6,2,FALSE()),0) -> 1 | K16: =IF(OR(F16="Fechado ganho",F16="Fechado perdido"),0,G16*J16) -> 0 | L16: =IF(OR(F16="Fechado ganho",F16="Fechado perdido"),"",Painel!$B$3-H16) | M16: =IF(AND(F16="Fechado perdido",I16=""),"Falta motivo da perda",IF(OR(F16="Fechado ganho",F16="Fechado perdido"),"",IF(Painel!$B$3-H16>7,"Sem contato há mais de 7 dias","OK"))) | N16: =MONTH(D16) -> 7
A17: N-015 | B17: Cliente 062 | C17: Site | D17: 46216 | E17: Atendente B | F17: Fechado perdido | G17: 4600 | H17: 46236 | I17: Desistiu do projeto | J17: =IFERROR(VLOOKUP(F17,Listas!$A$2:$B$6,2,FALSE()),0) -> 0 | K17: =IF(OR(F17="Fechado ganho",F17="Fechado perdido"),0,G17*J17) -> 0 | L17: =IF(OR(F17="Fechado ganho",F17="Fechado perdido"),"",Painel!$B$3-H17) | M17: =IF(AND(F17="Fechado perdido",I17=""),"Falta motivo da perda",IF(OR(F17="Fechado ganho",F17="Fechado perdido"),"",IF(Painel!$B$3-H17>7,"Sem contato há mais de 7 dias","OK"))) | N17: =MONTH(D17) -> 7
A18: N-016 | B18: Cliente 065 | C18: Indicação | D18: 46223 | E18: Atendente A | F18: Fechado ganho | G18: 13700 | H18: 46226 | J18: =IFERROR(VLOOKUP(F18,Listas!$A$2:$B$6,2,FALSE()),0) -> 1 | K18: =IF(OR(F18="Fechado ganho",F18="Fechado perdido"),0,G18*J18) -> 0 | L18: =IF(OR(F18="Fechado ganho",F18="Fechado perdido"),"",Painel!$B$3-H18) | M18: =IF(AND(F18="Fechado perdido",I18=""),"Falta motivo da perda",IF(OR(F18="Fechado ganho",F18="Fechado perdido"),"",IF(Painel!$B$3-H18>7,"Sem contato há mais de 7 dias","OK"))) | N18: =MONTH(D18) -> 7
A19: N-017 | B19: Cliente 001 | C19: Indicação | D19: 46224 | E19: Atendente A | F19: Fechado ganho | G19: 22900 | H19: 46235 | J19: =IFERROR(VLOOKUP(F19,Listas!$A$2:$B$6,2,FALSE()),0) -> 1 | K19: =IF(OR(F19="Fechado ganho",F19="Fechado perdido"),0,G19*J19) -> 0 | L19: =IF(OR(F19="Fechado ganho",F19="Fechado perdido"),"",Painel!$B$3-H19) | M19: =IF(AND(F19="Fechado perdido",I19=""),"Falta motivo da perda",IF(OR(F19="Fechado ganho",F19="Fechado perdido"),"",IF(Painel!$B$3-H19>7,"Sem contato há mais de 7 dias","OK"))) | N19: =MONTH(D19) -> 7
A20: N-018 | B20: Cliente 050 | C20: WhatsApp | D20: 46228 | E20: Atendente B | F20: Fechado ganho | G20: 9200 | H20: 46243 | J20: =IFERROR(VLOOKUP(F20,Listas!$A$2:$B$6,2,FALSE()),0) -> 1 | K20: =IF(OR(F20="Fechado ganho",F20="Fechado perdido"),0,G20*J20) -> 0 | L20: =IF(OR(F20="Fechado ganho",F20="Fechado perdido"),"",Painel!$B$3-H20) | M20: =IF(AND(F20="Fechado perdido",I20=""),"Falta motivo da perda",IF(OR(F20="Fechado ganho",F20="Fechado perdido"),"",IF(Painel!$B$3-H20>7,"Sem contato há mais de 7 dias","OK"))) | N20: =MONTH(D20) -> 7
A21: N-019 | B21: Cliente 046 | C21: Instagram | D21: 46231 | E21: Atendente B | F21: Fechado ganho | G21: 9900 | H21: 46245 | J21: =IFERROR(VLOOKUP(F21,Listas!$A$2:$B$6,2,FALSE()),0) -> 1 | K21: =IF(OR(F21="Fechado ganho",F21="Fechado perdido"),0,G21*J21) -> 0 | L21: =IF(OR(F21="Fechado ganho",F21="Fechado perdido"),"",Painel!$B$3-H21) | M21: =IF(AND(F21="Fechado perdido",I21=""),"Falta motivo da perda",IF(OR(F21="Fechado ganho",F21="Fechado perdido"),"",IF(Painel!$B$3-H21>7,"Sem contato há mais de 7 dias","OK"))) | N21: =MONTH(D21) -> 7
A22: N-020 | B22: Cliente 072 | C22: Indicação | D22: 46231 | E22: Atendente A | F22: Orçamento enviado | G22: 7600 | H22: 46306 | J22: =IFERROR(VLOOKUP(F22,Listas!$A$2:$B$6,2,FALSE()),0) -> 0.4 | K22: =IF(OR(F22="Fechado ganho",F22="Fechado perdido"),0,G22*J22) -> 3040 | L22: =IF(OR(F22="Fechado ganho",F22="Fechado perdido"),"",Painel!$B$3-H22) -> 4 | M22: =IF(AND(F22="Fechado perdido",I22=""),"Falta motivo da perda",IF(OR(F22="Fechado ganho",F22="Fechado perdido"),"",IF(Painel!$B$3-H22>7,"Sem contato há mais de 7 dias","OK"))) -> OK | N22: =MONTH(D22) -> 7
A23: N-021 | B23: Cliente 068 | C23: WhatsApp | D23: 46236 | E23: Atendente B | F23: Fechado perdido | G23: 18800 | H23: 46254 | I23: Preço | J23: =IFERROR(VLOOKUP(F23,Listas!$A$2:$B$6,2,FALSE()),0) -> 0 | K23: =IF(OR(F23="Fechado ganho",F23="Fechado perdido"),0,G23*J23) -> 0 | L23: =IF(OR(F23="Fechado ganho",F23="Fechado perdido"),"",Painel!$B$3-H23) | M23: =IF(AND(F23="Fechado perdido",I23=""),"Falta motivo da perda",IF(OR(F23="Fechado ganho",F23="Fechado perdido"),"",IF(Painel!$B$3-H23>7,"Sem contato há mais de 7 dias","OK"))) | N23: =MONTH(D23) -> 8
A24: N-022 | B24: Cliente 004 | C24: Instagram | D24: 46237 | E24: Atendente B | F24: Qualificação | G24: 7500 | H24: 46298 | J24: =IFERROR(VLOOKUP(F24,Listas!$A$2:$B$6,2,FALSE()),0) -> 0.1 | K24: =IF(OR(F24="Fechado ganho",F24="Fechado perdido"),0,G24*J24) -> 750 | L24: =IF(OR(F24="Fechado ganho",F24="Fechado perdido"),"",Painel!$B$3-H24) -> 12 | M24: =IF(AND(F24="Fechado perdido",I24=""),"Falta motivo da perda",IF(OR(F24="Fechado ganho",F24="Fechado perdido"),"",IF(Painel!$B$3-H24>7,"Sem contato há mais de 7 dias","OK"))) -> Sem contato há mais de 7 dias | N24: =MONTH(D24) -> 8
A25: N-023 | B25: Cliente 013 | C25: Instagram | D25: 46237 | E25: Atendente A | F25: Fechado ganho | G25: 21500 | H25: 46246 | J25: =IFERROR(VLOOKUP(F25,Listas!$A$2:$B$6,2,FALSE()),0) -> 1 | K25: =IF(OR(F25="Fechado ganho",F25="Fechado perdido"),0,G25*J25) -> 0 | L25: =IF(OR(F25="Fechado ganho",F25="Fechado perdido"),"",Painel!$B$3-H25) | M25: =IF(AND(F25="Fechado perdido",I25=""),"Falta motivo da perda",IF(OR(F25="Fechado ganho",F25="Fechado perdido"),"",IF(Painel!$B$3-H25>7,"Sem contato há mais de 7 dias","OK"))) | N25: =MONTH(D25) -> 8
A26: N-024 | B26: Cliente 029 | C26: Site | D26: 46239 | E26: Atendente B | F26: Fechado perdido | G26: 13600 | H26: 46252 | I26: Desistiu do projeto | J26: =IFERROR(VLOOKUP(F26,Listas!$A$2:$B$6,2,FALSE()),0) -> 0 | K26: =IF(OR(F26="Fechado ganho",F26="Fechado perdido"),0,G26*J26) -> 0 | L26: =IF(OR(F26="Fechado ganho",F26="Fechado perdido"),"",Painel!$B$3-H26) | M26: =IF(AND(F26="Fechado perdido",I26=""),"Falta motivo da perda",IF(OR(F26="Fechado ganho",F26="Fechado perdido"),"",IF(Painel!$B$3-H26>7,"Sem contato há mais de 7 dias","OK"))) | N26: =MONTH(D26) -> 8
A27: N-025 | B27: Cliente 045 | C27: Site | D27: 46239 | E27: Atendente A | F27: Fechado perdido | G27: 7500 | H27: 46242 | I27: Prazo | J27: =IFERROR(VLOOKUP(F27,Listas!$A$2:$B$6,2,FALSE()),0) -> 0 | K27: =IF(OR(F27="Fechado ganho",F27="Fechado perdido"),0,G27*J27) -> 0 | L27: =IF(OR(F27="Fechado ganho",F27="Fechado perdido"),"",Painel!$B$3-H27) | M27: =IF(AND(F27="Fechado perdido",I27=""),"Falta motivo da perda",IF(OR(F27="Fechado ganho",F27="Fechado perdido"),"",IF(Painel!$B$3-H27>7,"Sem contato há mais de 7 dias","OK"))) | N27: =MONTH(D27) -> 8
A28: N-026 | B28: Cliente 071 | C28: Instagram | D28: 46239 | E28: Atendente A | F28: Negociação | G28: 16500 | H28: 46308 | J28: =IFERROR(VLOOKUP(F28,Listas!$A$2:$B$6,2,FALSE()),0) -> 0.7 | K28: =IF(OR(F28="Fechado ganho",F28="Fechado perdido"),0,G28*J28) -> 11550 | L28: =IF(OR(F28="Fechado ganho",F28="Fechado perdido"),"",Painel!$B$3-H28) -> 2 | M28: =IF(AND(F28="Fechado perdido",I28=""),"Falta motivo da perda",IF(OR(F28="Fechado ganho",F28="Fechado perdido"),"",IF(Painel!$B$3-H28>7,"Sem contato há mais de 7 dias","OK"))) -> OK | N28: =MONTH(D28) -> 8
A29: N-027 | B29: Cliente 064 | C29: Indicação | D29: 46241 | E29: Atendente A | F29: Qualificação | G29: 23800 | H29: 46304 | J29: =IFERROR(VLOOKUP(F29,Listas!$A$2:$B$6,2,FALSE()),0) -> 0.1 | K29: =IF(OR(F29="Fechado ganho",F29="Fechado perdido"),0,G29*J29) -> 2380 | L29: =IF(OR(F29="Fechado ganho",F29="Fechado perdido"),"",Painel!$B$3-H29) -> 6 | M29: =IF(AND(F29="Fechado perdido",I29=""),"Falta motivo da perda",IF(OR(F29="Fechado ganho",F29="Fechado perdido"),"",IF(Painel!$B$3-H29>7,"Sem contato há mais de 7 dias","OK"))) -> OK | N29: =MONTH(D29) -> 8
A30: N-028 | B30: Cliente 063 | C30: Instagram | D30: 46245 | E30: Atendente B | F30: Orçamento enviado | G30: 9300 | H30: 46304 | J30: =IFERROR(VLOOKUP(F30,Listas!$A$2:$B$6,2,FALSE()),0) -> 0.4 | K30: =IF(OR(F30="Fechado ganho",F30="Fechado perdido"),0,G30*J30) -> 3720 | L30: =IF(OR(F30="Fechado ganho",F30="Fechado perdido"),"",Painel!$B$3-H30) -> 6 | M30: =IF(AND(F30="Fechado perdido",I30=""),"Falta motivo da perda",IF(OR(F30="Fechado ganho",F30="Fechado perdido"),"",IF(Painel!$B$3-H30>7,"Sem contato há mais de 7 dias","OK"))) -> OK | N30: =MONTH(D30) -> 8
A31: N-029 | B31: Cliente 020 | C31: Instagram | D31: 46246 | E31: Atendente A | F31: Fechado ganho | G31: 12400 | H31: 46265 | J31: =IFERROR(VLOOKUP(F31,Listas!$A$2:$B$6,2,FALSE()),0) -> 1 | K31: =IF(OR(F31="Fechado ganho",F31="Fechado perdido"),0,G31*J31) -> 0 | L31: =IF(OR(F31="Fechado ganho",F31="Fechado perdido"),"",Painel!$B$3-H31) | M31: =IF(AND(F31="Fechado perdido",I31=""),"Falta motivo da perda",IF(OR(F31="Fechado ganho",F31="Fechado perdido"),"",IF(Painel!$B$3-H31>7,"Sem contato há mais de 7 dias","OK"))) | N31: =MONTH(D31) -> 8
A32: N-030 | B32: Cliente 056 | C32: Indicação | D32: 46252 | E32: Atendente A | F32: Orçamento enviado | G32: 22400 | H32: 46308 | J32: =IFERROR(VLOOKUP(F32,Listas!$A$2:$B$6,2,FALSE()),0) -> 0.4 | K32: =IF(OR(F32="Fechado ganho",F32="Fechado perdido"),0,G32*J32) -> 8960 | L32: =IF(OR(F32="Fechado ganho",F32="Fechado perdido"),"",Painel!$B$3-H32) -> 2 | M32: =IF(AND(F32="Fechado perdido",I32=""),"Falta motivo da perda",IF(OR(F32="Fechado ganho",F32="Fechado perdido"),"",IF(Painel!$B$3-H32>7,"Sem contato há mais de 7 dias","OK"))) -> OK | N32: =MONTH(D32) -> 8
A33: N-031 | B33: Cliente 002 | C33: Site | D33: 46253 | E33: Atendente A | F33: Fechado perdido | G33: 11500 | H33: 46256 | I33: Prazo | J33: =IFERROR(VLOOKUP(F33,Listas!$A$2:$B$6,2,FALSE()),0) -> 0 | K33: =IF(OR(F33="Fechado ganho",F33="Fechado perdido"),0,G33*J33) -> 0 | L33: =IF(OR(F33="Fechado ganho",F33="Fechado perdido"),"",Painel!$B$3-H33) | M33: =IF(AND(F33="Fechado perdido",I33=""),"Falta motivo da perda",IF(OR(F33="Fechado ganho",F33="Fechado perdido"),"",IF(Painel!$B$3-H33>7,"Sem contato há mais de 7 dias","OK"))) | N33: =MONTH(D33) -> 8
A34: N-032 | B34: Cliente 024 | C34: WhatsApp | D34: 46253 | E34: Atendente A | F34: Fechado ganho | G34: 11100 | H34: 46260 | J34: =IFERROR(VLOOKUP(F34,Listas!$A$2:$B$6,2,FALSE()),0) -> 1 | K34: =IF(OR(F34="Fechado ganho",F34="Fechado perdido"),0,G34*J34) -> 0 | L34: =IF(OR(F34="Fechado ganho",F34="Fechado perdido"),"",Painel!$B$3-H34) | M34: =IF(AND(F34="Fechado perdido",I34=""),"Falta motivo da perda",IF(OR(F34="Fechado ganho",F34="Fechado perdido"),"",IF(Painel!$B$3-H34>7,"Sem contato há mais de 7 dias","OK"))) | N34: =MONTH(D34) -> 8
A35: N-033 | B35: Cliente 051 | C35: Indicação | D35: 46256 | E35: Atendente A | F35: Fechado ganho | G35: 9700 | H35: 46259 | J35: =IFERROR(VLOOKUP(F35,Listas!$A$2:$B$6,2,FALSE()),0) -> 1 | K35: =IF(OR(F35="Fechado ganho",F35="Fechado perdido"),0,G35*J35) -> 0 | L35: =IF(OR(F35="Fechado ganho",F35="Fechado perdido"),"",Painel!$B$3-H35) | M35: =IF(AND(F35="Fechado perdido",I35=""),"Falta motivo da perda",IF(OR(F35="Fechado ganho",F35="Fechado perdido"),"",IF(Painel!$B$3-H35>7,"Sem contato há mais de 7 dias","OK"))) | N35: =MONTH(D35) -> 8
A36: N-034 | B36: Cliente 047 | C36: Instagram | D36: 46259 | E36: Atendente B | F36: Orçamento enviado | G36: 5200 | H36: 46305 | J36: =IFERROR(VLOOKUP(F36,Listas!$A$2:$B$6,2,FALSE()),0) -> 0.4 | K36: =IF(OR(F36="Fechado ganho",F36="Fechado perdido"),0,G36*J36) -> 2080 | L36: =IF(OR(F36="Fechado ganho",F36="Fechado perdido"),"",Painel!$B$3-H36) -> 5 | M36: =IF(AND(F36="Fechado perdido",I36=""),"Falta motivo da perda",IF(OR(F36="Fechado ganho",F36="Fechado perdido"),"",IF(Painel!$B$3-H36>7,"Sem contato há mais de 7 dias","OK"))) -> OK | N36: =MONTH(D36) -> 8
A37: N-035 | B37: Cliente 060 | C37: WhatsApp | D37: 46260 | E37: Atendente A | F37: Qualificação | G37: 3100 | H37: 46300 | J37: =IFERROR(VLOOKUP(F37,Listas!$A$2:$B$6,2,FALSE()),0) -> 0.1 | K37: =IF(OR(F37="Fechado ganho",F37="Fechado perdido"),0,G37*J37) -> 310 | L37: =IF(OR(F37="Fechado ganho",F37="Fechado perdido"),"",Painel!$B$3-H37) -> 10 | M37: =IF(AND(F37="Fechado perdido",I37=""),"Falta motivo da perda",IF(OR(F37="Fechado ganho",F37="Fechado perdido"),"",IF(Painel!$B$3-H37>7,"Sem contato há mais de 7 dias","OK"))) -> Sem contato há mais de 7 dias | N37: =MONTH(D37) -> 8
A38: N-036 | B38: Cliente 026 | C38: WhatsApp | D38: 46264 | E38: Atendente B | F38: Fechado ganho | G38: 5100 | H38: 46282 | J38: =IFERROR(VLOOKUP(F38,Listas!$A$2:$B$6,2,FALSE()),0) -> 1 | K38: =IF(OR(F38="Fechado ganho",F38="Fechado perdido"),0,G38*J38) -> 0 | L38: =IF(OR(F38="Fechado ganho",F38="Fechado perdido"),"",Painel!$B$3-H38) | M38: =IF(AND(F38="Fechado perdido",I38=""),"Falta motivo da perda",IF(OR(F38="Fechado ganho",F38="Fechado perdido"),"",IF(Painel!$B$3-H38>7,"Sem contato há mais de 7 dias","OK"))) | N38: =MONTH(D38) -> 8
A39: N-037 | B39: Cliente 009 | C39: Indicação | D39: 46266 | E39: Atendente B | F39: Negociação | G39: 22700 | H39: 46300 | J39: =IFERROR(VLOOKUP(F39,Listas!$A$2:$B$6,2,FALSE()),0) -> 0.7 | K39: =IF(OR(F39="Fechado ganho",F39="Fechado perdido"),0,G39*J39) -> 15890 | L39: =IF(OR(F39="Fechado ganho",F39="Fechado perdido"),"",Painel!$B$3-H39) -> 10 | M39: =IF(AND(F39="Fechado perdido",I39=""),"Falta motivo da perda",IF(OR(F39="Fechado ganho",F39="Fechado perdido"),"",IF(Painel!$B$3-H39>7,"Sem contato há mais de 7 dias","OK"))) -> Sem contato há mais de 7 dias | N39: =MONTH(D39) -> 9
A40: N-038 | B40: Cliente 021 | C40: Indicação | D40: 46266 | E40: Atendente A | F40: Fechado perdido | G40: 6500 | H40: 46283 | I40: Preço | J40: =IFERROR(VLOOKUP(F40,Listas!$A$2:$B$6,2,FALSE()),0) -> 0 | K40: =IF(OR(F40="Fechado ganho",F40="Fechado perdido"),0,G40*J40) -> 0 | L40: =IF(OR(F40="Fechado ganho",F40="Fechado perdido"),"",Painel!$B$3-H40) | M40: =IF(AND(F40="Fechado perdido",I40=""),"Falta motivo da perda",IF(OR(F40="Fechado ganho",F40="Fechado perdido"),"",IF(Painel!$B$3-H40>7,"Sem contato há mais de 7 dias","OK"))) | N40: =MONTH(D40) -> 9
...

Sheet Instalacoes
A1: INSTALAÇÕES (criadas quando o negócio é ganho)
A2: ID | B2: Negócio | C2: Cliente | D2: Data agendada | E2: Instalador | F2: Status | G2: Checklist concluído | H2: Alerta
A3: I-001 | B3: N-001 | C3: =IFERROR(INDEX(Negocios!$B$3:$B$82,MATCH(B3,Negocios!$A$3:$A$82,0)),"Negócio não encontrado") -> Cliente 067 | D3: 46299 | E3: Instalador C | F3: Concluída e validada | G3: Não | H3: =IF(F3="Concluída e validada",IF(G3="Sim","OK","Falta checklist"),IF(D3<Painel!$B$3,"Atrasada","No prazo")) -> Falta checklist
A4: I-002 | B4: N-002 | C4: =IFERROR(INDEX(Negocios!$B$3:$B$82,MATCH(B4,Negocios!$A$3:$A$82,0)),"Negócio não encontrado") -> Cliente 022 | D4: 46255 | E4: Instalador A | F4: Concluída e validada | G4: Sim | H4: =IF(F4="Concluída e validada",IF(G4="Sim","OK","Falta checklist"),IF(D4<Painel!$B$3,"Atrasada","No prazo")) -> OK
A5: I-003 | B5: N-003 | C5: =IFERROR(INDEX(Negocios!$B$3:$B$82,MATCH(B5,Negocios!$A$3:$A$82,0)),"Negócio não encontrado") -> Cliente 007 | D5: 46285 | E5: Instalador A | F5: Concluída e validada | G5: Sim | H5: =IF(F5="Concluída e validada",IF(G5="Sim","OK","Falta checklist"),IF(D5<Painel!$B$3,"Atrasada","No prazo")) -> OK
A6: I-004 | B6: N-004 | C6: =IFERROR(INDEX(Negocios!$B$3:$B$82,MATCH(B6,Negocios!$A$3:$A$82,0)),"Negócio não encontrado") -> Cliente 023 | D6: 46254 | E6: Instalador C | F6: Concluída e validada | G6: Sim | H6: =IF(F6="Concluída e validada",IF(G6="Sim","OK","Falta checklist"),IF(D6<Painel!$B$3,"Atrasada","No prazo")) -> OK
A7: I-005 | B7: N-005 | C7: =IFERROR(INDEX(Negocios!$B$3:$B$82,MATCH(B7,Negocios!$A$3:$A$82,0)),"Negócio não encontrado") -> Cliente 066 | D7: 46308 | E7: Instalador B | F7: Em execução | G7: Não | H7: =IF(F7="Concluída e validada",IF(G7="Sim","OK","Falta checklist"),IF(D7<Painel!$B$3,"Atrasada","No prazo")) -> Atrasada
A8: I-006 | B8: N-006 | C8: =IFERROR(INDEX(Negocios!$B$3:$B$82,MATCH(B8,Negocios!$A$3:$A$82,0)),"Negócio não encontrado") -> Cliente 027 | D8: 46269 | E8: Instalador C | F8: Concluída e validada | G8: Sim | H8: =IF(F8="Concluída e validada",IF(G8="Sim","OK","Falta checklist"),IF(D8<Painel!$B$3,"Atrasada","No prazo")) -> OK
A9: I-007 | B9: N-007 | C9: =IFERROR(INDEX(Negocios!$B$3:$B$82,MATCH(B9,Negocios!$A$3:$A$82,0)),"Negócio não encontrado") -> Cliente 052 | D9: 46310 | E9: Instalador C | F9: Em execução | G9: Não | H9: =IF(F9="Concluída e validada",IF(G9="Sim","OK","Falta checklist"),IF(D9<Painel!$B$3,"Atrasada","No prazo")) -> No prazo
A10: I-008 | B10: N-008 | C10: =IFERROR(INDEX(Negocios!$B$3:$B$82,MATCH(B10,Negocios!$A$3:$A$82,0)),"Negócio não encontrado") -> Cliente 008 | D10: 46268 | E10: Instalador B | F10: Concluída e validada | G10: Sim | H10: =IF(F10="Concluída e validada",IF(G10="Sim","OK","Falta checklist"),IF(D10<Painel!$B$3,"Atrasada","No prazo")) -> OK
A11: I-009 | B11: N-011 | C11: =IFERROR(INDEX(Negocios!$B$3:$B$82,MATCH(B11,Negocios!$A$3:$A$82,0)),"Negócio não encontrado") -> Cliente 075 | D11: 46314 | E11: Instalador B | F11: Agendada | G11: Não | H11: =IF(F11="Concluída e validada",IF(G11="Sim","OK","Falta checklist"),IF(D11<Painel!$B$3,"Atrasada","No prazo")) -> No prazo
A12: I-010 | B12: N-012 | C12: =IFERROR(INDEX(Negocios!$B$3:$B$82,MATCH(B12,Negocios!$A$3:$A$82,0)),"Negócio não encontrado") -> Cliente 015 | D12: 46307 | E12: Instalador C | F12: Material conferido | G12: Não | H12: =IF(F12="Concluída e validada",IF(G12="Sim","OK","Falta checklist"),IF(D12<Painel!$B$3,"Atrasada","No prazo")) -> Atrasada
A13: I-011 | B13: N-013 | C13: =IFERROR(INDEX(Negocios!$B$3:$B$82,MATCH(B13,Negocios!$A$3:$A$82,0)),"Negócio não encontrado") -> Cliente 074 | D13: 46312 | E13: Instalador B | F13: Agendada | G13: Não | H13: =IF(F13="Concluída e validada",IF(G13="Sim","OK","Falta checklist"),IF(D13<Painel!$B$3,"Atrasada","No prazo")) -> No prazo
A14: I-012 | B14: N-014 | C14: =IFERROR(INDEX(Negocios!$B$3:$B$82,MATCH(B14,Negocios!$A$3:$A$82,0)),"Negócio não encontrado") -> Cliente 033 | D14: 46312 | E14: Instalador B | F14: Material conferido | G14: Não | H14: =IF(F14="Concluída e validada",IF(G14="Sim","OK","Falta checklist"),IF(D14<Painel!$B$3,"Atrasada","No prazo")) -> No prazo
... A30: I-028 | B30: N-061 | C30: =IFERROR(INDEX(Negocios!$B$3:$B$82,MATCH(B30,Negocios!$A$3:$A$82,0)),"Negócio não encontrado") -> Cliente 057 | D30: 46308 | E30: Instalador A | F30: Em execução | G30: Não | H30: =IF(F30="Concluída e validada",IF(G30="Sim","OK","Falta checklist"),IF(D30<Painel!$B$3,"Atrasada","No prazo")) -> Atrasada

Sheet Reparos
A1: REPAROS (tickets ligados à instalação)
A2: ID | B2: Instalação | C2: Cliente | D2: Causa | E2: Status | F2: Data de abertura | G2: Dias em aberto | H2: Alerta
A3: R-001 | B3: I-020 | C3: =IFERROR(INDEX(Instalacoes!$C$3:$C$30,MATCH(B3,Instalacoes!$A$3:$A$30,0)),"Instalação não encontrada") -> Cliente 051 | D3: Dano após a instalação | E3: Aberto | F3: 46309 | G3: =IF(E3="Resolvido","",Painel!$B$3-F3) -> 1 | H3: =IF(G3="","",IF(G3>7,"Aberto há mais de 7 dias","OK")) -> OK
A4: R-002 | B4: I-026 | C4: =IFERROR(INDEX(Instalacoes!$C$3:$C$30,MATCH(B4,Instalacoes!$A$3:$A$30,0)),"Instalação não encontrada") -> Cliente 048 | D4: Falha de aplicação | E4: Em análise | F4: 46300 | G4: =IF(E4="Resolvido","",Painel!$B$3-F4) -> 10 | H4: =IF(G4="","",IF(G4>7,"Aberto há mais de 7 dias","OK")) -> Aberto há mais de 7 dias
A5: R-003 | B5: I-024 | C5: =IFERROR(INDEX(Instalacoes!$C$3:$C$30,MATCH(B5,Instalacoes!$A$3:$A$30,0)),"Instalação não encontrada") -> Cliente 039 | D5: Falha de aplicação | E5: Aguardando material | F5: 46298 | G5: =IF(E5="Resolvido","",Painel!$B$3-F5) -> 12 | H5: =IF(G5="","",IF(G5>7,"Aberto há mais de 7 dias","OK")) -> Aberto há mais de 7 dias
A6: R-004 | B6: I-018 | C6: =IFERROR(INDEX(Instalacoes!$C$3:$C$30,MATCH(B6,Instalacoes!$A$3:$A$30,0)),"Instalação não encontrada") -> Cliente 020 | D6: Material com defeito | E6: Reparo agendado | F6: 46305 | G6: =IF(E6="Resolvido","",Painel!$B$3-F6) -> 5 | H6: =IF(G6="","",IF(G6>7,"Aberto há mais de 7 dias","OK")) -> OK
A7: R-005 | B7: I-004 | C7: =IFERROR(INDEX(Instalacoes!$C$3:$C$30,MATCH(B7,Instalacoes!$A$3:$A$30,0)),"Instalação não encontrada") -> Cliente 023 | D7: Medida incorreta | E7: Resolvido | F7: 46303 | G7: =IF(E7="Resolvido","",Painel!$B$3-F7) | H7: =IF(G7="","",IF(G7>7,"Aberto há mais de 7 dias","OK"))
A8: R-006 | B8: I-019 | C8: =IFERROR(INDEX(Instalacoes!$C$3:$C$30,MATCH(B8,Instalacoes!$A$3:$A$30,0)),"Instalação não encontrada") -> Cliente 024 | D8: Dano após a instalação | E8: Resolvido | F8: 46309 | G8: =IF(E8="Resolvido","",Painel!$B$3-F8) | H8: =IF(G8="","",IF(G8>7,"Aberto há mais de 7 dias","OK"))
A9: R-007 | B9: I-002 | C9: =IFERROR(INDEX(Instalacoes!$C$3:$C$30,MATCH(B9,Instalacoes!$A$3:$A$30,0)),"Instalação não encontrada") -> Cliente 022 | D9: Material com defeito | E9: Resolvido | F9: 46299 | G9: =IF(E9="Resolvido","",Painel!$B$3-F9) | H9: =IF(G9="","",IF(G9>7,"Aberto há mais de 7 dias","OK"))
A10: R-008 | B10: I-013 | C10: =IFERROR(INDEX(Instalacoes!$C$3:$C$30,MATCH(B10,Instalacoes!$A$3:$A$30,0)),"Instalação não encontrada") -> Cliente 065 | D10: Medida incorreta | E10: Resolvido | F10: 46309 | G10: =IF(E10="Resolvido","",Painel!$B$3-F10) | H10: =IF(G10="","",IF(G10>7,"Aberto há mais de 7 dias","OK"))

Sheet Contas
A1: CONTAS: SAÚDE DO CLIENTE (health score)
A2: Cliente | B2: Health score (0 a 100) | C2: Status de saúde
A3: Cliente 067 | B3: 88 | C3: =IF(B3>=80,"Saudável",IF(B3>=50,"Atenção","Risco")) -> Saudável
A4: Cliente 022 | B4: 76 | C4: =IF(B4>=80,"Saudável",IF(B4>=50,"Atenção","Risco")) -> Atenção
A5: Cliente 007 | B5: 76 | C5: =IF(B5>=80,"Saudável",IF(B5>=50,"Atenção","Risco")) -> Atenção
A6: Cliente 023 | B6: 76 | C6: =IF(B6>=80,"Saudável",IF(B6>=50,"Atenção","Risco")) -> Atenção
A7: Cliente 066 | B7: 72 | C7: =IF(B7>=80,"Saudável",IF(B7>=50,"Atenção","Risco")) -> Atenção
A8: Cliente 027 | B8: 52 | C8: =IF(B8>=80,"Saudável",IF(B8>=50,"Atenção","Risco")) -> Atenção
A9: Cliente 052 | B9: 52 | C9: =IF(B9>=80,"Saudável",IF(B9>=50,"Atenção","Risco")) -> Atenção
A10: Cliente 008 | B10: 52 | C10: =IF(B10>=80,"Saudável",IF(B10>=50,"Atenção","Risco")) -> Atenção
A11: Cliente 075 | B11: 66 | C11: =IF(B11>=80,"Saudável",IF(B11>=50,"Atenção","Risco")) -> Atenção
A12: Cliente 015 | B12: 52 | C12: =IF(B12>=80,"Saudável",IF(B12>=50,"Atenção","Risco")) -> Atenção
A13: Cliente 074 | B13: 47 | C13: =IF(B13>=80,"Saudável",IF(B13>=50,"Atenção","Risco")) -> Risco
A14: Cliente 033 | B14: 85 | C14: =IF(B14>=80,"Saudável",IF(B14>=50,"Atenção","Risco")) -> Saudável
... A30: Cliente 057 | B30: 84 | C30: =IF(B30>=80,"Saudável",IF(B30>=50,"Atenção","Risco")) -> Saudável

Sheet Listas
A1: Fase do negócio | B1: Probabilidade | D1: Status da instalação | F1: Causa do reparo | H1: Status do reparo | J1: Origem | L1: Motivo da perda
A2: Qualificação | B2: 0.1 | D2: Agendada | F2: Falha de aplicação | H2: Aberto | J2: WhatsApp | L2: Preço
A3: Orçamento enviado | B3: 0.4 | D3: Material conferido | F3: Material com defeito | H3: Em análise | J3: Instagram | L3: Prazo
A4: Negociação | B4: 0.7 | D4: Em execução | F4: Preparo inadequado do local | H4: Aguardando material | J4: Indicação | L4: Escolheu outro fornecedor
A5: Fechado ganho | B5: 1 | D5: Concluída e validada | F5: Medida incorreta | H5: Reparo agendado | J5: Site | L5: Desistiu do projeto
A6: Fechado perdido | B6: 0 | F6: Dano após a instalação | H6: Resolvido
A8: Probabilidades por fase: premissa de exemplo, editável.
